---
title: エラーチャネル操作
excerpt: Effectにおけるエラーチャネルのさまざまな操作について探ります。エラーマッピング、両チャネルマッピング、成功値のフィルタリング、エラーの検査、エラーの公開、エラーと成功チャネルのマージ、エラーと成功チャネルの反転などを含みます。Effectプログラミングでエラーを効果的に処理する方法を学びましょう。
bottomNavigation: pagination
---

Effectでは、エフェクトのエラーチャネルに対してさまざまな操作を行うことができます。これらの操作により、エラーを変換、検査、および処理する方法が提供されます。これらの操作のいくつかを見てみましょう。

## マップ操作

### mapError

`Effect.mapError`関数は、成功値に影響を与えずに、エフェクトによって生成されたエラーを**変換または修正**する必要がある場合に使用されます。これは、エラーに追加情報を加えたり、エラーの型を変更したりする場合に役立ちます。

```ts twoslash
import { Effect } from "effect"

const simulatedTask = Effect.fail("Oh no!").pipe(Effect.as(1))

const mapped = Effect.mapError(simulatedTask, (message) => new Error(message))
```

エラーチャネルの型が`string`から`Error`に変わったことがわかります。

<Info>
  `Effect.mapError`関数を使用しても、エフェクトの全体的な成功または失敗は**変わりません**。
  マッピングされたエフェクトが成功した場合、マッピング関数は無視されます。
  言い換えれば、`Effect.mapError`操作はエフェクトのエラーチャネルにのみ変換を適用し、成功チャネルは変更されません。
</Info>

### mapBoth

`Effect.mapBoth`関数を使用すると、エフェクトのエラーチャネルと成功チャネルの**両方に変換を適用**することができます。エラーチャネル用と成功チャネル用の2つのマップ関数を引数として取ります。

```ts twoslash
import { Effect } from "effect"

const simulatedTask = Effect.fail("Oh no!").pipe(Effect.as(1))

const modified = Effect.mapBoth(simulatedTask, {
  onFailure: (message) => new Error(message),
  onSuccess: (n) => n > 0
})
```

`mapBoth`を使用すると、プログラムの型が`Effect<number, string>`から`Effect<boolean, Error>`に変わったことがわかります。

<Info>
  `mapBoth`関数を使用しても、エフェクトの全体的な成功または失敗は**変わりません**。
  これは、エラーチャネルと成功チャネルの値を変換するだけで、エフェクトの元の成功または失敗の状態を保持します。
</Info>

## 成功チャネルのフィルタリング

Effectライブラリは、指定された述語に基づいて**成功チャネルの値をフィルタリング**するためのいくつかのオペレーターを提供します。これらのオペレーターは、述語が失敗した場合の処理方法に関して異なる戦略を提供します。見てみましょう：

| **関数**                                                | **説明**                                                                                                                                                                                                                               |
| ------------------------------------------------------- | -------------------------------------------------------------------------------------------------------------------------------------------------------------------------------------------------------------------------------------- |
| `Effect.filterOrFail`                                   | このオペレーターは、述語に基づいて成功チャネルの値をフィルタリングします。述語が任意の値に対して失敗した場合、元のエフェクトはエラーで失敗します。                                                                                     |
| `Effect.filterOrDie` および `Effect.filterOrDieMessage` | これらのオペレーターも述語に基づいて成功チャネルの値をフィルタリングします。述語が任意の値に対して失敗した場合、元のエフェクトは突然終了します。`filterOrDieMessage`バリアントでは、カスタムエラーメッセージを提供することができます。 |
| `Effect.filterOrElse`                                   | このオペレーターは、述語に基づいて成功チャネルの値をフィルタリングします。述語が任意の値に対して失敗した場合、代替のエフェクトが実行されます。                                                                                         |

これらのフィルタリングオペレーターが実際にどのように動作するかを示す例を見てみましょう：

```ts twoslash
import { Effect, Random, Cause } from "effect"

const task1 = Effect.filterOrFail(
  Random.nextRange(-1, 1),
  (n) => n >= 0,
  () => "random number is negative"
)

const task2 = Effect.filterOrDie(
  Random.nextRange(-1, 1),
  (n) => n >= 0,
  () => new Cause.IllegalArgumentException("random number is negative")
)

const task3 = Effect.filterOrDieMessage(
  Random.nextRange(-1, 1),
  (n) => n >= 0,
  "random number is negative"
)

const task4 = Effect.filterOrElse(
  Random.nextRange(-1, 1),
  (n) => n >= 0,
  () => task3
)
```

特定のフィルタリングオペレーターを使用することにより、述語が失敗した場合、エフェクトが失敗するか、突然終了するか、代替のエフェクトを実行するかのいずれかになることに注意してください。エラーハンドリングの戦略とプログラムのロジックに基づいて、適切なオペレーターを選択してください。

前述のフィルタリング機能に加えて、`filterOr*` APIに[ユーザー定義の型ガード](https://www.typescriptlang.org/docs/handbook/2/narrowing.html#using-type-predicates)を提供することで、成功チャネルの型をさらに絞り込むことができます。これにより、型の安全性が向上し、コードの明確さも向上します。例を通じてこの概念を見てみましょう：

```ts twoslash
import { Effect, pipe } from "effect"

// ユーザーインターフェースを定義する
interface User {
  readonly name: string
}

// 非同期認証関数を仮定する
declare const auth: () => Promise<User | null>

const program = pipe(
  Effect.promise(() => auth()),
  Effect.filterOrFail(
    // 型を絞り込むためのガードを定義する
    (user): user is User => user !== null,
    () => new Error("Unauthorized")
  ),
  Effect.andThen((user) => user.name) // ここでの 'user' は `User | null` ではなく、`User` 型です
)
```

上記の例では、`filterOrFail` API内でガードを使用して、`user`が`User | null`ではなく`User`型であることを保証しています。この精緻化された型情報により、コードの信頼性が向上し、理解しやすくなります。

好みに応じて、シンプルさと一貫性のために[Predicate.isNotNull](https://effect-ts.github.io/effect/effect/Predicate.ts.html#isnotnull)のような既製のガードを利用することもできます。

## エラーの検査

成功値の[タッピング](../essentials/pipeline#tap)と同様に、Effectは**エラー値を検査する**ための複数のオペレーターを提供しています。これらのオペレーターにより、開発者は結果を変更せずに失敗や根本的な問題を観察することができます：

| 関数            | 説明                                                                                                                       |
| --------------- | -------------------------------------------------------------------------------------------------------------------------- |
| `tapError`      | エフェクトの失敗を変更せずに検査するための効果的な操作を実行します。                                                       |
| `tapErrorTag`   | 特定のタグを持つ失敗を具体的に検査し、焦点を絞ったエラー処理を可能にします。                                               |
| `tapErrorCause` | エフェクトの失敗の根本原因を検査します。                                                                                   |
| `tapDefect`     | エフェクト内の回復不可能な失敗や欠陥（つまり、1つ以上の[Die](../../other/data-types/cause#die)原因）を具体的に検査します。 |
| `tapBoth`       | エフェクトの成功と失敗の両方の結果を検査し、結果に基づいて異なるアクションを実行します。                                   |

<Info>
  これらのエラー検査ツールを使用しても、エフェクトの結果や型は**変更されません**。
</Info>

### tapError

エフェクトの失敗を変更せずに検査するための効果的な操作を実行します。

```ts twoslash
import { Effect, Console } from "effect"

// ネットワークエラーの発生をシミュレートするために、失敗するように設計されたエフェクトを作成する
const task: Effect.Effect<number, string> = Effect.fail("NetworkError")

// タスクが失敗した場合にエラーメッセージをログに記録します。この関数はエラーがある場合にのみ実行され、
// 元のエフェクトの結果を変更せずにエラーを処理または検査する方法を提供します。
const tapping = Effect.tapError(task, (error) =>
  Console.log(`expected error: ${error}`)
)

Effect.runFork(tapping)
/*
出力:
expected error: NetworkError
*/
```

### tapErrorTag

特定のタグを持つ失敗を具体的に検査し、焦点を絞ったエラー処理を可能にします。

```ts twoslash
import { Effect, Console } from "effect"

class NetworkError {
  readonly _tag = "NetworkError"
  constructor(readonly statusCode: number) {}
}

class ValidationError {
  readonly _tag = "ValidationError"
  constructor(readonly field: string) {}
}

// ネットワークエラーの発生をシミュレートするために、失敗するように設計されたエフェクトを作成する
const task: Effect.Effect<number, NetworkError | ValidationError> =
  Effect.fail(new NetworkError(504))

// "NetworkError"とタグ付けされたエラーにのみエラー処理関数を適用し、
// エラーの対応するステータスコードをログに記録します。
const tapping = Effect.tapErrorTag(task, "NetworkError", (error) =>
  Console.log(`expected error: ${error.statusCode}`)
)

Effect.runFork(tapping)
/*
出力:
expected error: 504
*/
```

### tapErrorCause

エフェクトの失敗の根本的な原因を検査します。

```ts
import { Effect, Console } from "effect"

// ネットワークエラーの発生をシミュレートするために、失敗するように設計されたエフェクトを作成する
const task1: Effect.Effect<number, string> = Effect.fail("NetworkError")

// これは予期されるエラーや欠陥の原因をログに記録します
const tapping1 = Effect.tapErrorCause(task1, (cause) =>
  Console.log(`error cause: ${cause}`)
)

Effect.runFork(tapping1)
/*
出力:
error cause: Error: NetworkError
*/

// 特定のメッセージを持つ欠陥を引き起こすことで、システムの重大な障害をシミュレートします。
const task2: Effect.Effect<number, string> = Effect.dieMessage(
  "Something went wrong"
)

// これは予期されるエラーや欠陥の原因をログに記録します
const tapping2 = Effect.tapErrorCause(task2, (cause) =>
  Console.log(`error cause: ${cause}`)
)

Effect.runFork(tapping2)
/*
出力:
error cause: RuntimeException: Something went wrong
  ... stack trace ...
*/
```

### tapDefect

エフェクトの回復不可能な失敗または欠陥（つまり、1つ以上の[Die](../../other/data-types/cause#die)原因）を特に検査します。

```ts
import { Effect, Console } from "effect"

// ネットワークエラーの発生をシミュレートするために、失敗するように設計されたエフェクトを作成する
const task1: Effect.Effect<number, string> = Effect.fail("NetworkError")

// これは欠陥ではないため、何もログに記録されません
const tapping1 = Effect.tapDefect(task1, (cause) =>
  Console.log(`defect: ${cause}`)
)

Effect.runFork(tapping1)
/*
No Output
*/

// 特定のメッセージを持つ欠陥を引き起こすことで、システムの重大な障害をシミュレートします。
const task2: Effect.Effect<number, string> = Effect.dieMessage(
  "Something went wrong"
)

// これはエラーではなく欠陥のみをログに記録します
const tapping2 = Effect.tapDefect(task2, (cause) =>
  Console.log(`defect: ${cause}`)
)

Effect.runFork(tapping2)
/*
出力:
defect: RuntimeException: Something went wrong
  ... stack trace ...
*/
```

### tapBoth

エフェクトの成功と失敗の両方の結果を検査し、結果に基づいて異なるアクションを実行します。

```ts twoslash
import { Effect, Random, Console } from "effect"

// 失敗する可能性のあるエフェクトをシミュレートする
const task = Effect.filterOrFail(
  Random.nextRange(-1, 1),
  (n) => n >= 0,
  () => "random number is negative"
)

// 'task'の成功と失敗の両方の結果をログに記録するエフェクトを定義する
const tapping = Effect.tapBoth(task, {
  onFailure: (error) => Console.log(`failure: ${error}`),
  onSuccess: (randomNumber) => Console.log(`random number: ${randomNumber}`)
})

Effect.runFork(tapping)
/*
出力の例:
failure: random number is negative
*/
```

## 成功チャネルでのエラーの公開

`Effect.either`関数を使用して、`Effect<A, E, R>`を、失敗（`E`）と成功（`A`）の両方のチャネルが[Either&lt;A, E&gt;](../../other/data-types/either)データ型に持ち上げられた別のエフェクトに変換することができます：

```ts
Effect<A, E, R> -> Effect<Either<A, E>, never, R>
```

結果として得られるエフェクトは例外のないエフェクトであり、失敗することはありません。なぜなら、失敗のケースが`Either`の左側のケースとして公開されているからです。したがって、返されるEffectのエラーパラメータは`never`であり、エフェクトが失敗をモデル化しないことが保証されています。

この関数は、`Effect.gen`を使用して失敗する可能性のあるエフェクトから回復する際に特に有用です。

<Tabs items={["Effect.genを使用する", "pipeを使用する"]}>
<Tab>

```ts twoslash
import { Effect, Either, Console } from "effect"

const simulatedTask = Effect.fail("Oh uh!").pipe(Effect.as(2))

const program = Effect.gen(function* () {
  const failureOrSuccess = yield* Effect.either(simulatedTask)
  if (Either.isLeft(failureOrSuccess)) {
    const error = failureOrSuccess.left
    yield* Console.log(`failure: ${error}`)
    return 0
  } else {
    const value = failureOrSuccess.right
    yield* Console.log(`success: ${value}`)
    return value
  }
})
```

</Tab>
<Tab>

```ts twoslash
import { Effect, Either, Console } from "effect"

const simulatedTask = Effect.fail("Oh uh!").pipe(Effect.as(2))

const program = Effect.either(simulatedTask).pipe(
  Effect.andThen((failureOrSuccess) =>
    Either.match(failureOrSuccess, {
      onLeft: (error) => Console.log(`failure: ${error}`).pipe(Effect.as(0)),
      onRight: (value) =>
        Console.log(`success: ${value}`).pipe(Effect.as(value))
    })
  )
)
```

</Tab>
</Tabs>

## 成功チャネルで原因を公開する

`Effect.cause`関数を使用して、エフェクトの原因を公開することができます。これは、エラーメッセージや欠陥を含む失敗のより詳細な表現です。

<Tabs items={["Effect.genを使用する", "pipeを使用する"]}>
<Tab>

```ts twoslash
import { Effect, Console } from "effect"

const simulatedTask = Effect.fail("Oh uh!").pipe(Effect.as(2))

const program = Effect.gen(function* () {
  const cause = yield* Effect.cause(simulatedTask)
  yield* Console.log(cause)
})
```

</Tab>
<Tab>

```ts twoslash
import { Effect, Console } from "effect"

const simulatedTask = Effect.fail("Oh uh!").pipe(Effect.as(2))

const program = Effect.cause(simulatedTask).pipe(
  Effect.andThen((cause) => Console.log(cause))
)
```

</Tab>
</Tabs>

## エラーチャネルを成功チャネルに統合する

`Effect.merge`関数を使用すると、**エラーチャネルを成功チャネルに統合**することができ、統合された値で常に成功するエフェクトを作成します。

```ts twoslash
import { Effect } from "effect"

const simulatedTask = Effect.fail("Oh uh!").pipe(Effect.as(2))

const merged = Effect.merge(simulatedTask)
```

## エラーチャネルと成功チャネルの反転

`Effect.flip`関数を使用すると、エフェクトの**エラーチャネルと成功チャネルを反転**させ、それぞれの役割を効果的に入れ替えることができます。

```ts twoslash
import { Effect } from "effect"

const simulatedTask = Effect.fail("Oh uh!").pipe(Effect.as(2))

const flipped = Effect.flip(simulatedTask)
```
