---
title: 並列および逐次エラー
excerpt: Effectプログラミングにおける並列および逐次エラーの処理方法を学びます。並列計算や逐次操作に関わるエラーハンドリングの挙動を理解します。複数の並列失敗を効率的に露出し処理するためのコンビネータ`Effect.parallelErrors`を探求します。
bottomNavigation: pagination
---

通常のEffectアプリケーションでは、エラーが発生すると、Effectランタイムによって最初に遭遇したエラーで失敗します。例を見てみましょう：

```ts twoslash
import { Effect } from "effect"

const fail = Effect.fail("Oh uh!")
const die = Effect.dieMessage("Boom!")

const program = Effect.all([fail, die]).pipe(
  Effect.andThen(die),
  Effect.asVoid
)

Effect.runPromiseExit(program).then(console.log)
/*
出力:
{
  _id: 'Exit',
  _tag: 'Failure',
  cause: { _id: 'Cause', _tag: 'Fail', failure: 'Oh uh!' }
}
*/
```

この場合、`program`は最初のエラーである「Oh uh!」で失敗します。

## 並列エラー

しかし、場合によっては、特に並列計算を行う際に複数のエラーに遭遇することがあります。並列計算が関与する場合、アプリケーションは複数のエラーによって失敗することがあります。以下はその例です：

```ts twoslash
import { Effect } from "effect"

const fail = Effect.fail("Oh uh!")
const die = Effect.dieMessage("Boom!")

const program = Effect.all([fail, die], { concurrency: "unbounded" }).pipe(
  Effect.asVoid
)

Effect.runPromiseExit(program).then(console.log)
/*
出力:
{
  _id: 'Exit',
  _tag: 'Failure',
  cause: {
    _id: 'Cause',
    _tag: 'Parallel',
    left: { _id: 'Cause', _tag: 'Fail', failure: 'Oh uh!' },
    right: { _id: 'Cause', _tag: 'Die', defect: [Object] }
  }
}
*/
```

この例では、`program`は`fail`と`die`の両方を並列に実行し、両方が失敗した場合、複数のエラーが発生します。

### parallelErrors

Effectは、エラーチャンネル内のすべての並列失敗エラーを公開する便利なコンビネータ`Effect.parallelErrors`を提供します。以下はその使用方法です：

```ts twoslash
import { Effect } from "effect"

const fail1 = Effect.fail("Oh uh!")
const fail2 = Effect.fail("Oh no!")
const die = Effect.dieMessage("Boom!")

const program = Effect.all([fail1, fail2, die], {
  concurrency: "unbounded"
}).pipe(Effect.asVoid, Effect.parallelErrors)

Effect.runPromiseExit(program).then(console.log)
/*
出力:
{
  _id: 'Exit',
  _tag: 'Failure',
  cause: { _id: 'Cause', _tag: 'Fail', failure: [ 'Oh uh!', 'Oh no!' ] }
}
*/
```

この例では、`Effect.parallelErrors`は`fail1`と`fail2`のエラーを1つのエラーに結合します。

<Warning>
  このオペレーターは**失敗**のためのものであり、欠陥や中断のためのものではないことに注意してください。
</Warning>

## 逐次エラー

`Effect.ensuring`のようなリソース安全オペレーターを使用する場合、複数の逐次エラーに遭遇することがあります。これは、元のエフェクトにエラーがあるかどうかに関係なく、ファイナライザーが中断不可能で実行されるためです。以下はその例です：

```ts twoslash
import { Effect } from "effect"

const fail = Effect.fail("Oh uh!")
const die = Effect.dieMessage("Boom!")

const program = fail.pipe(Effect.ensuring(die))

Effect.runPromiseExit(program).then(console.log)
/*
出力:
{
  _id: 'Exit',
  _tag: 'Failure',
  cause: {
    _id: 'Cause',
    _tag: 'Sequential',
    left: { _id: 'Cause', _tag: 'Fail', failure: 'Oh uh!' },
    right: { _id: 'Cause', _tag: 'Die', defect: [Object] }
  }
}
*/
```

この場合、`fail`とファイナライザーの`die`の両方がエラーに遭遇すると、`program`は複数の逐次エラーを引き起こします。
