---
title: イールド可能なエラー
excerpt: Effectプログラミングにおける「Yieldable Errors」について学びましょう。これはジェネレータ関数内でカスタムエラーを扱う便利な方法です。`Data.Error`と`Data.TaggedError`コンストラクタを使って、基本的およびタグ付きのyieldableエラーを作成し、コード内のエラー処理を簡素化します。
bottomNavigation: pagination
---

「Yieldable Errors」は、`Effect.gen`で使用される[ジェネレータ関数](../essentials/using-generators)内でyieldできる特別な種類のエラーです。これらのエラーのユニークな特徴は、`Effect.fail` APIを明示的に使用する必要がないことです。これにより、カスタムエラーをより直感的かつ便利に扱うことができます。

## Data.Error

`Data.Error`コンストラクタを使用すると、基本的なyieldableエラークラスを作成できます。このクラスは、コード内のさまざまな種類のエラーを表現するために使用できます。以下はその使用方法です：

```ts twoslash
import { Effect, Data } from "effect"

class MyError extends Data.Error<{ message: string }> {}

export const program = Effect.gen(function* () {
  yield* new MyError({ message: "Oh no!" }) // これは yield* Effect.fail(new MyError({ message: "Oh no!" }) と同じです
})

Effect.runPromiseExit(program).then(console.log)
/*
出力:
{
  _id: 'Exit',
  _tag: 'Failure',
  cause: { _id: 'Cause', _tag: 'Fail', failure: { message: 'Oh no!' } }
}
*/
```

## Data.TaggedError

`Data.TaggedError`コンストラクタは、タグ付きのyieldableエラーを作成するのに便利です。これらのエラーは、ユニークな識別子として機能する`_tag`という特別なプロパティを持ち、エラーを区別することができます。以下はその使用方法です：

```ts twoslash
import { Effect, Data, Random } from "effect"

// _tagが"Foo"のエラー
class FooError extends Data.TaggedError("Foo")<{
  message: string
}> {}

// _tagが"Bar"のエラー
class BarError extends Data.TaggedError("Bar")<{
  randomNumber: number
}> {}

export const program = Effect.gen(function* () {
  const n = yield* Random.next
  return n > 0.5
    ? "yay!"
    : n < 0.2
      ? yield* new FooError({ message: "Oh no!" })
      : yield* new BarError({ randomNumber: n })
}).pipe(
  Effect.catchTags({
    Foo: (error) => Effect.succeed(`Foo error: ${error.message}`),
    Bar: (error) => Effect.succeed(`Bar error: ${error.randomNumber}`)
  })
)

Effect.runPromise(program).then(console.log, console.error)
/*
例の出力 (n < 0.2):
Foo error: Oh no!
*/
```

この例では、異なるタグ ("Foo" と "Bar") を持つ `FooError` と `BarError` クラスを作成します。これらのタグは、コード内でエラーを処理する際にエラーの種類を識別するのに役立ちます。
