---
title: 予期されたエラー
excerpt: Effectが予期されたエラーをどのように表現し管理するかを探ります。エラーインスタンスの作成、型レベルでのエラー追跡、Effectプログラムのショートサーキット動作について学びます。エラーをキャッチして回復する技術を発見し、Effectの強力なコンビネータを使用したエラーハンドリング戦略についての洞察を得ます。
bottomNavigation: pagination
---

このガイドでは以下を学びます：

- Effectが予期されたエラーをどのように表現するか
- Effectが提供する堅牢で包括的なエラーマネジメントツール

ガイド[Effectの作成](../essentials/creating-effects)で見たように、`fail`コンストラクタを使用してエラーを表すEffectを作成できます：

```ts twoslash
import { Effect } from "effect"

class HttpError {
  readonly _tag = "HttpError"
}

const program = Effect.fail(new HttpError())
```

<Info>
  上記の`HttpError`型を表現するためにクラスを使用していますが、
  これはエラータイプとフリーコンストラクタの両方にアクセスするためです。
  しかし、エラータイプをモデル化するために好きなものを使用することができます。
</Info>

この例では、エラーの識別子としてreadonlyの`_tag`フィールドを追加していることに注意してください：

```ts {1}
class HttpError {
  readonly _tag = "HttpError"
}
```

<Idea>
  `_tag`のような識別フィールドを追加することは、エラーハンドリング中に異なる種類のエラーを区別するのに役立ちます。
  また、TypeScriptが型を統一するのを防ぎ、各エラーがその識別値に基づいて個別に扱われることを保証します。
</Idea>

予期されたエラーは、`Effect`データ型の「Error」チャネルで**型レベルで追跡されます**。

`program`の型から、`HttpError`型のエラーで失敗する可能性があることが明らかです：

```ts
Effect<never, HttpError, never>
```

## エラーの追跡

次のプログラムは、エラーが自動的に追跡される方法を示す例です：

<Tabs items={["Using Effect.gen", "Using pipe"]}>
<Tab>

```twoslash include error-tracking
import { Effect, Random } from "effect"

export class FooError {
  readonly _tag = "FooError"
}

export class BarError {
  readonly _tag = "BarError"
}

export const program = Effect.gen(function* () {
  const n1 = yield* Random.next
  const n2 = yield* Random.next

  const foo = n1 > 0.5 ? "yay!" : yield* Effect.fail(new FooError())

  const bar = n2 > 0.5 ? "yay!" : yield* Effect.fail(new BarError())

  return foo + bar
})
```

```ts filename="error-tracking.ts" twoslash
// @include: error-tracking

Effect.runPromise(program).then(console.log, console.error)
```

上記のプログラムでは、`foo`と`bar`という2つの値を計算しており、それぞれがエラーの潜在的な原因を表しています。

</Tab>
<Tab>

```ts filename="error-tracking.ts" twoslash
import { Effect, Random } from "effect"

export class FooError {
  readonly _tag = "FooError"
}

export class BarError {
  readonly _tag = "BarError"
}

const flakyFoo = Random.next.pipe(
  Effect.andThen((n1) =>
    n1 > 0.5 ? Effect.succeed("yay!") : Effect.fail(new FooError())
  )
)

const flakyBar = Random.next.pipe(
  Effect.andThen((n2) =>
    n2 > 0.5 ? Effect.succeed("yay!") : Effect.fail(new BarError())
  )
)

export const program = Effect.all([flakyFoo, flakyBar]).pipe(
  Effect.andThen(([foo, bar]) => foo + bar)
)
```

上記のプログラムでは、`flakyFoo`と`flakyBar`という2つの操作があり、それぞれがエラーの潜在的な原因を表しています。
これらの操作は、Effectライブラリの`Effect.all(effects){:ts}`関数を使用して組み合わせることができ、これにより一連の操作として実行することができます。

</Tab>
</Tabs>

Effectはプログラムの実行中に発生する可能性のあるエラーを自動的に追跡します。
この場合、`FooError`と`BarError`が考えられるエラータイプです。
プログラムのエラーチャンネルは次のように指定されています

```ts
Effect<string, FooError | BarError, never>
```

これは、`FooError`または`BarError`のいずれかで失敗する可能性があることを示しています。

## ショートサーキット

`Effect.gen`、`Effect.map`、`Effect.flatMap`、`Effect.andThen`、`Effect.all`のようなAPIを使用する際には、これらがエラーをどのように処理するかを理解することが重要です。
これらのAPIは、**最初のエラー**に遭遇した時点で**実行をショートサーキット**するように設計されています。

開発者として、これはどういう意味でしょうか？例えば、一連の操作やエフェクトのコレクションを順番に実行する場合を考えてみましょう。これらのエフェクトの実行中にエラーが発生した場合、残りの計算はスキップされ、そのエラーが最終結果に伝播されます。

簡単に言えば、ショートサーキットの動作は、プログラムのどのステップで問題が発生しても、不要な計算を実行する時間を無駄にしないことを保証します。代わりに、すぐに停止してエラーを返し、何が問題だったかを知らせてくれます。

<Tabs items={["Using Effect.gen", "Using pipe"]}>
<Tab>

```ts twoslash
import { Effect, Console } from "effect"

// 3つの異なるタスクを表すエフェクトを定義します。
const task1 = Console.log("Executing task1...")
const task2 = Effect.fail("Something went wrong!")
const task3 = Console.log("Executing task3...")

// 3つのタスクを順番に実行するように構成します。
// もし1つのタスクが失敗した場合、後続のタスクは実行されません。
const program = Effect.gen(function* () {
  yield* task1
  yield* task2 // task1の後にtask2が実行されますが、エラーで失敗します
  yield* task3 // 前の計算が失敗するため、この計算は実行されません
})

Effect.runPromiseExit(program).then(console.log)
/*
出力:
Executing task1...
{
  _id: 'Exit',
  _tag: 'Failure',
  cause: { _id: 'Cause', _tag: 'Fail', failure: 'Something went wrong!' }
}
*/
```

</Tab>
<Tab>

```ts twoslash
import { Effect, Console } from "effect"

// 3つの異なるタスクを表すエフェクトを定義します。
const task1 = Console.log("Executing task1...")
const task2 = Effect.fail("Something went wrong!")
const task3 = Console.log("Executing task3...")

// 3つのタスクを`Effect.andThen`を使って順番に実行するように構成します。
// `Effect.andThen`関数を使うことで、エフェクトを連鎖させることができます。
// もし1つのタスクが失敗した場合、後続のタスクは実行されません。
const program = task1.pipe(
  Effect.andThen(task2), // task1の後にtask2が実行されますが、エラーで失敗します
  Effect.andThen(task3) // 前の計算が失敗するため、この計算は実行されません
)

Effect.runPromiseExit(program).then(console.log)
/*
出力:
Executing task1...
{
  _id: 'Exit',
  _tag: 'Failure',
  cause: { _id: 'Cause', _tag: 'Fail', failure: 'Something went wrong!' }
}
*/
```

</Tab>
</Tabs>

このコードスニペットは、エラーが発生したときのショートサーキット動作を示しています。
各操作は前の操作が成功することに依存しています。
もしエラーが発生した場合、実行はショートサーキットされ、エラーが伝播されます。
この具体的な例では、`task2`でエラーが発生するため、`task3`は実行されません。

## すべてのエラーをキャッチする

### either

`Effect.either`関数は、`Effect<A, E, R>`を、失敗（`E`）と成功（`A`）の両方のチャネルが[Either&lt;A, E&gt;](../../other/data-types/either)データ型に持ち上げられた別のエフェクトに変換します：

```ts
Effect<A, E, R> -> Effect<Either<A, E>, never, R>
```

[Either&lt;R, L&gt;](../../other/data-types/either) データ型は、`Right` 値 (`R`) または `Left` 値 (`L`) のいずれかを表す値です。
`Either` を使用することで、この型に対して「パターンマッチ」を行い、ジェネレータ関数内で失敗と成功の両方のケースを処理する能力を得ることができます。

```ts twoslash
// @filename: error-tracking.ts
// @include: error-tracking

// @filename: index.ts
// ---cut---
import { Effect, Either } from "effect"
import { program } from "./error-tracking"

const recovered = Effect.gen(function* () {
  const failureOrSuccess = yield* Effect.either(program)
  if (Either.isLeft(failureOrSuccess)) {
    // 失敗の場合: `left` プロパティからエラーを抽出できます
    const error = failureOrSuccess.left
    return `Recovering from ${error._tag}`
  } else {
    // 成功の場合: `right` プロパティから値を抽出できます
    return failureOrSuccess.right
  }
})
```

`Either.match` 関数を使用することで、エラーと成功の値を処理するための2つのコールバック関数を直接受け取るため、コードをより簡潔にすることができます。

```ts twoslash
// @filename: error-tracking.ts
// @include: error-tracking

// @filename: index.ts
// ---cut---
import { Effect, Either } from "effect"
import { program } from "./error-tracking"

const recovered = Effect.gen(function* () {
  const failureOrSuccess = yield* Effect.either(program)
  return Either.match(failureOrSuccess, {
    onLeft: (error) => `Recovering from ${error._tag}`,
    onRight: (value) => value // 成功の場合は何もしない
  })
})
```

### catchAll

`Effect.catchAll` 関数は、プログラム内で発生するあらゆるエラーをキャッチし、フォールバックを提供することができます。

```ts {5} twoslash
// @filename: error-tracking.ts
// @include: error-tracking

// @filename: index.ts
// ---cut---
import { Effect } from "effect"
import { program } from "./error-tracking"

const recovered = program.pipe(
  Effect.catchAll((error) => Effect.succeed(`Recovering from ${error._tag}`))
)
```

エラーチャンネルの型が `never` に変わったことが確認できます。これは、すべてのエラーが処理されたことを示しています。

## 特定のエラーをキャッチする

例えば、`FooError` のような特定のエラーを処理したいとします。

```ts {8-10} twoslash
// @filename: error-tracking.ts
// @include: error-tracking

// @filename: index.ts
// ---cut---
import { Effect, Either } from "effect"
import { program } from "./error-tracking"

const recovered = Effect.gen(function* () {
  const failureOrSuccess = yield* Effect.either(program)
  if (Either.isLeft(failureOrSuccess)) {
    const error = failureOrSuccess.left
    if (error._tag === "FooError") {
      return "Recovering from FooError"
    }
    return yield* Effect.fail(error)
  } else {
    return failureOrSuccess.right
  }
})
```

プログラムのエラーチャンネルの型が `BarError` のみを示すように変わったことが確認できます。これは、`FooError` が処理されたことを示しています。

もし `BarError` も処理したい場合は、簡単に別のケースをコードに追加することができます。

```ts {11} twoslash
// @filename: error-tracking.ts
// @include: error-tracking

// @filename: index.ts
// ---cut---
import { Effect, Either } from "effect"
import { program } from "./error-tracking"

const recovered = Effect.gen(function* () {
  const failureOrSuccess = yield* Effect.either(program)
  if (Either.isLeft(failureOrSuccess)) {
    const error = failureOrSuccess.left
    if (error._tag === "FooError") {
      return "Recovering from FooError"
    } else {
      return "Recovering from BarError"
    }
  } else {
    return failureOrSuccess.right
  }
})
```

プログラムのエラーチャンネルの型が `never` に変わったことが確認できます。これは、すべてのエラーが処理されたことを示しています。

### catchSome

特定の種類のエラーのみをキャッチして回復を試みたい場合は、`Effect.catchSome` 関数を使用できます。

```ts twoslash
// @filename: error-tracking.ts
// @include: error-tracking

// @filename: index.ts
// ---cut---
import { Effect, Option } from "effect"
import { program } from "./error-tracking"

const recovered = program.pipe(
  Effect.catchSome((error) => {
    if (error._tag === "FooError") {
      return Option.some(Effect.succeed("Recovering from FooError"))
    }
    return Option.none()
  })
)
```

上記のコードでは、`Effect.catchSome` はエラー (`error`) を調べて回復を試みるかどうかを決定する関数を受け取ります。エラーが特定の条件に一致する場合、`Option.some(effect)` を返すことで回復を試みることができます。回復が不可能な場合は、単に `Option.none()` を返すことができます。

重要なのは、`Effect.catchSome` は特定のエラーをキャッチすることができる一方で、**エラーの型自体を変更しない**という点です。したがって、結果として得られるエフェクト（この場合は `recovered`）は、元のエフェクトと同じエラー型 (`FooError | BarError`) を持ち続けます。

### catchIf

`Effect.catchSome` と同様に、`Effect.catchIf` 関数は、述語に基づいて特定のエラーから回復することを可能にします：

```ts twoslash
// @filename: error-tracking.ts
// @include: error-tracking

// @filename: index.ts
// ---cut---
import { Effect } from "effect"
import { program } from "./error-tracking"

const recovered = program.pipe(
  Effect.catchIf(
    (error) => error._tag === "FooError",
    () => Effect.succeed("Recovering from FooError")
  )
)
```

`Effect.catchIf` は特定のエラーをキャッチすることができますが、**エラーの型自体を変更しない**ことに注意が必要です。したがって、結果として得られるエフェクト（この場合は `recovered`）は、元のエフェクトと同じエラー型 (`FooError | BarError`) を持ち続けます。

しかし、述語の代わりに[ユーザー定義の型ガード](https://www.typescriptlang.org/docs/handbook/2/narrowing.html#using-type-predicates)を提供すると、結果のエラー型が絞り込まれ、`Effect<string, BarError, never>` が返されます：

```ts {6} twoslash
// @filename: error-tracking.ts
// @include: error-tracking

// @filename: index.ts
// ---cut---
import { Effect } from "effect"
import { program, FooError } from "./error-tracking"

const recovered = program.pipe(
  Effect.catchIf(
    (error): error is FooError => error._tag === "FooError",
    () => Effect.succeed("Recovering from FooError")
  )
)
```

### catchTag

プログラムのエラーがすべて識別子として機能する `_tag` フィールドでタグ付けされている場合、`Effect.catchTag` 関数を使用して特定のエラーを正確にキャッチして処理することができます。

```ts {5-7} twoslash
// @filename: error-tracking.ts
// @include: error-tracking

// @filename: index.ts
// ---cut---
import { Effect } from "effect"
import { program } from "./error-tracking"

const recovered = program.pipe(
  Effect.catchTag("FooError", (_fooError) =>
    Effect.succeed("Recovering from FooError")
  )
)
```

上記の例では、`Effect.catchTag` 関数を使用して `FooError` を特定して処理することができます。
プログラムの実行中に `FooError` が発生した場合、提供されたエラーハンドラ関数が呼び出され、
ハンドラ内で指定されたリカバリロジックに従ってプログラムが進行します。

プログラムのエラーチャンネルの型が `BarError` のみを示すように変わったことが観察できます。
これは `FooError` が処理されたことを示しています。

もし `BarError` も処理したい場合は、別の `catchTag` を追加するだけです：

```ts {8-10} twoslash
// @filename: error-tracking.ts
// @include: error-tracking

// @filename: index.ts
// ---cut---
import { Effect } from "effect"
import { program } from "./error-tracking"

const recovered = program.pipe(
  Effect.catchTag("FooError", (_fooError) =>
    Effect.succeed("Recovering from FooError")
  ),
  Effect.catchTag("BarError", (_barError) =>
    Effect.succeed("Recovering from BarError")
  )
)
```

プログラムのエラーチャンネルの型が `never` に変わったことが観察できます。
これはすべてのエラーが処理されたことを示しています。

<Warning>
  `catchTag` で使用するエラー型には `readonly _tag`
  判別フィールドが必要であることを
  確認することが重要です。このフィールドは特定のエラータグをマッチングし、
  処理するために必要です。
</Warning>

### catchTags

個々のエラータイプを処理するために `Effect.catchTag` 関数を複数回使用する代わりに、
より便利なオプションとして `Effect.catchTags` があります。`Effect.catchTags` を使用すると、
1つのコードブロックで複数のエラーを処理することができます。

```ts {5-8} twoslash
// @filename: error-tracking.ts
// @include: error-tracking

// @filename: index.ts
// ---cut---
import { Effect } from "effect"
import { program } from "./error-tracking"

const recovered = program.pipe(
  Effect.catchTags({
    FooError: (_fooError) => Effect.succeed(`Recovering from FooError`),
    BarError: (_barError) => Effect.succeed(`Recovering from BarError`)
  })
)
```

上記の例では、個々のエラーを処理するために `Effect.catchTag` を複数回使用する代わりに、`Effect.catchTags` コンビネータを利用しています。
このコンビネータは、各プロパティが特定のエラー `_tag`（この場合は `"FooError"` と `"BarError"`）を表し、
対応する値がその特定のエラーが発生したときに実行されるエラーハンドラ関数であるオブジェクトを受け取ります。

<Warning>
  `Effect.catchTags` で使用するすべてのエラータイプに `readonly _tag`
  判別フィールドがあることを確認することが重要です。
  このフィールドは特定のエラータグをマッチングし、処理するために必要です。
</Warning>
