---
title: 予期しないエラー
excerpt: Effectが`die`、`dieMessage`、`orDie`、`orDieWith`などの関数を提供し、回復不能なエラー（欠陥）をどのように処理するかを学びます。エフェクトの実行を終了し、予期しないエラーを処理し、欠陥から回復するための技術を探ります。`catchAllDefect`および`catchSomeDefect`を使用して、特定の欠陥を管理し、選択的に回復する方法を発見します。
bottomNavigation: pagination
---

予期しないエラーに遭遇する状況があり、それらをどのように処理するかを決定する必要があります。Effectはそのようなシナリオに対処するための関数を提供し、エフェクトの実行中にエラーが発生した場合に適切なアクションを取ることができます。

## 回復不能なエラーの作成

`fail`のようなコンビネータを利用して`Effect<never, E, never>`型の値を作成するのと同じように、Effectライブラリは欠陥を作成するためのツールを提供します。

ビジネスロジックの観点から回復不可能なエラー、例えば複数回の再試行後に接続が拒否される場合などに対処する際に、欠陥を作成することは一般的な必要性です。

そのような場合、エフェクトの実行を終了し、stdoutや外部の監視サービスなどの出力を通じて報告に移行することが最良の解決策となるかもしれません。

以下の関数とコンビネータはエフェクトの終了を可能にし、`Effect<A, E, R>`型の値を`Effect<A, never, R>`型の値に変換するために使用されることが多く、プログラマーが回復不可能なエラーを処理し回復する必要がない逃げ道を提供します。

### die / dieMessage

`Effect.die`関数は指定されたエラーをスローするエフェクトを返し、`Effect.dieMessage`は指定されたテキストメッセージを持つ`RuntimeException`をスローします。これらの関数は、コード内で重大で予期しないエラー（欠陥）が検出されたときにファイバーを終了するのに役立ちます。

`die`を使用した例：

```ts twoslash
import { Effect } from "effect"

const divide = (a: number, b: number): Effect.Effect<number> =>
  b === 0
    ? Effect.die(new Error("Cannot divide by zero"))
    : Effect.succeed(a / b)

Effect.runSync(divide(1, 0)) // エラーをスロー: ゼロで割ることはできません
```

`dieMessage`を使用した例:

```ts twoslash
import { Effect } from "effect"

const divide = (a: number, b: number): Effect.Effect<number> =>
  b === 0 ? Effect.dieMessage("Cannot divide by zero") : Effect.succeed(a / b)

Effect.runSync(divide(1, 0)) // ランタイム例外をスロー: ゼロで割ることはできません
```

### orDie

`Effect.orDie`関数は、エフェクトの失敗をファイバーの終了に変換し、すべての失敗をチェックされないものにし、エフェクトの型の一部ではなくします。回復したくないエラーを処理するために使用できます。

```ts twoslash
import { Effect } from "effect"

const divide = (a: number, b: number): Effect.Effect<number, Error> =>
  b === 0
    ? Effect.fail(new Error("Cannot divide by zero"))
    : Effect.succeed(a / b)

const program = Effect.orDie(divide(1, 0))

Effect.runSync(program) // エラーをスロー: ゼロで割ることはできません
```

`Effect.orDie`を使用した後、`program`のエラーチャネルの型は`never`となり、すべての失敗がチェックされず、エフェクトがエラー発生時にファイバーを終了することが期待されます。

### orDieWith

`Effect.orDie`と同様に、`Effect.orDieWith`関数は指定されたマッピング関数を使用してエフェクトの失敗をファイバーの終了に変換します。これにより、ファイバーを終了する前にエラーメッセージをカスタマイズすることができます。

```ts twoslash
import { Effect } from "effect"

const divide = (a: number, b: number): Effect.Effect<number, Error> =>
  b === 0
    ? Effect.fail(new Error("Cannot divide by zero"))
    : Effect.succeed(a / b)

const program = Effect.orDieWith(
  divide(1, 0),
  (error) => new Error(`defect: ${error.message}`)
)

Effect.runSync(program) // エラーをスロー: 欠陥: ゼロで割ることはできません
```

`Effect.orDieWith`を使用した後、`program`のエラーチャネルの型は`Effect.orDie`と同様に`never`となります。

## キャッチング

Effectは、エフェクトの実行中に発生する予期しないエラーを処理するための2つの関数を提供します。

<Warning>
  欠陥から回復するための合理的な方法はありません。
  これから説明する関数は、Effectと外部システムの境界でのみ使用し、
  診断や説明のために欠陥に関する情報を伝達するために使用するべきです。
</Warning>

### catchAllDefect

`Effect.catchAllDefect`関数は、提供された関数を使用してすべての欠陥から回復することを可能にします。以下はその例です：

```ts twoslash
import { Effect, Cause, Console } from "effect"

const program = Effect.catchAllDefect(
  Effect.dieMessage("Boom!"), // ランタイムエラーをシミュレート
  (defect) => {
    if (Cause.isRuntimeException(defect)) {
      return Console.log(`RuntimeException defect caught: ${defect.message}`)
    }
    return Console.log("Unknown defect caught.")
  }
)

// すべての欠陥をキャッチしたため、Exit.Successを取得します
Effect.runPromiseExit(program).then(console.log)
/*
出力:
ランタイム例外の欠陥をキャッチしました: Boom!
{
  _id: "Exit",
  _tag: "Success",
  value: undefined
}
*/
```

`catchAllDefect`は欠陥のみを処理でき、予期されたエラー（例えば`Effect.fail`によって引き起こされるもの）や実行の中断（例えば`Effect.interrupt`を使用する場合）を処理できないことを理解することが重要です。

欠陥とは、事前に予測できず、信頼できる対応方法がないエラーを指します。一般的なルールとして、欠陥はアプリケーションをクラッシュさせることが推奨されます。なぜなら、それらはしばしば対処が必要な重大な問題を示しているからです。

しかし、動的にロードされるプラグインを扱う場合など、特定のケースでは制御された回復アプローチが必要になることがあります。例えば、アプリケーションがプラグインのランタイムロードをサポートしており、プラグイン内で欠陥が発生した場合、アプリケーション全体をクラッシュさせるのではなく、欠陥をログに記録し、影響を受けたプラグインのみをリロードすることを選択するかもしれません。これにより、アプリケーションのより堅牢で中断のない運用が可能になります。

### catchSomeDefect

`Effect.catchSomeDefect`関数は、提供された部分関数を使用して特定の欠陥から回復することを可能にします。例を見てみましょう：

```ts twoslash
import { Effect, Cause, Option, Console } from "effect"

const program = Effect.catchSomeDefect(
  Effect.dieMessage("ドカン！"), // ランタイムエラーをシミュレート
  (defect) => {
    if (Cause.isIllegalArgumentException(defect)) {
      return Option.some(
        Console.log(
          `Caught an IllegalArgumentException defect: ${defect.message}`
        )
      )
    }
    return Option.none()
  }
)

// IllegalArgumentExceptionのみをキャッチしているため
// ランタイムエラーをシミュレートした結果、Exit.Failureを取得します。
Effect.runPromiseExit(program).then(console.log)
/*
Output:
{
  _id: "Exit",
  _tag: "Failure",
  cause: {
    _id: "Cause",
    _tag: "Die",
    defect: {
      _tag: "RuntimeException",
      message: "Boom!",
      [Symbol(@effect/io/Cause/errors/RuntimeException)]: Symbol(@effect/io/Cause/errors/RuntimeException),
      toString: [Function: toString]
    }
  }
}
*/
```

`catchSomeDefect`は欠陥のみを処理でき、[予期されたエラー](expected-errors)（例えば`Effect.fail`によって引き起こされるもの）や実行の中断（例えば`Effect.interrupt`を使用する場合）を処理できないことを理解することが重要です。
