---
title: マッチング
excerpt: "`match`や`matchEffect`のような関数を使用して、Effectデータ型における成功と失敗の両方のケースを処理する方法を学びます。副作用を実行し、値を無視し、失敗の原因を完全に把握する技術を学びます。Effectプログラムでの制御フローを効果的に管理し、エラーを処理します。"
bottomNavigation: pagination
---

`Effect`データ型では、[Option](../../other/data-types/option#matching)や[Exit](../../other/data-types/exit#matching)などの他のデータ型と同様に、異なるケースを同時に処理できる`match`関数があります。エフェクトを扱う際には、成功と失敗の両方のシナリオを処理するためのいくつかの関数もあります。

## match

`Effect.match`関数は、各ケースに対してハンドラを提供することにより、非エフェクト的な方法で**成功と失敗の両方のケースを処理**することができます：

```ts twoslash
import { Effect } from "effect"

const success: Effect.Effect<number, Error> = Effect.succeed(42)
const failure: Effect.Effect<number, Error> = Effect.fail(new Error("Uh oh!"))

const program1 = Effect.match(success, {
  onFailure: (error) => `failure: ${error.message}`,
  onSuccess: (value) => `success: ${value}`
})

Effect.runPromise(program1).then(console.log) // 出力: "success: 42"

const program2 = Effect.match(failure, {
  onFailure: (error) => `failure: ${error.message}`,
  onSuccess: (value) => `success: ${value}`
})

Effect.runPromise(program2).then(console.log) // 出力: "failure: Uh oh!"
```

成功と失敗の値に興味がない場合、それらを無視することもできます：

```ts twoslash
import { Effect } from "effect"
import { constVoid } from "effect/Function"

const task = Effect.fail("Uh oh!").pipe(Effect.as(5))

const program = Effect.match(task, {
  onFailure: constVoid,
  onSuccess: constVoid
})
```

この場合、`Function`モジュールの`constVoid`関数を使用します。この関数は常に`void`を返し、何も操作を行わないハンドラを提供します。これにより、成功と失敗の値を効果的に無視し、プログラムの制御フローや副作用にのみ焦点を当てることができます。代わりに、`Effect.ignore`関数を使用して同じ結果を達成することもできます：

```ts twoslash
import { Effect } from "effect"

const task = Effect.fail("Uh oh!").pipe(Effect.as(5))

const program = Effect.ignore(task)
```

## matchEffect

`Effect.match`に加えて、`Effect.matchEffect`関数もあります。この関数を使用すると、成功と失敗のケースを処理しながら**追加の副作用**を実行することができます。例を見てみましょう：

```ts twoslash
import { Effect } from "effect"

const success: Effect.Effect<number, Error> = Effect.succeed(42)
const failure: Effect.Effect<number, Error> = Effect.fail(new Error("Uh oh!"))

const program1 = Effect.matchEffect(success, {
  onFailure: (error) =>
    Effect.succeed(`failure: ${error.message}`).pipe(Effect.tap(Effect.log)),
  onSuccess: (value) =>
    Effect.succeed(`success: ${value}`).pipe(Effect.tap(Effect.log))
})

console.log(Effect.runSync(program1))
/*
出力:
... message="success: 42"
success: 42
*/

const program2 = Effect.matchEffect(failure, {
  onFailure: (error) =>
    Effect.succeed(`failure: ${error.message}`).pipe(Effect.tap(Effect.log)),
  onSuccess: (value) =>
    Effect.succeed(`success: ${value}`).pipe(Effect.tap(Effect.log))
})

console.log(Effect.runSync(program2))
/*
出力:
... message="failure: Uh oh!"
failure: Uh oh!
*/
```

この例では、`Effect.match`の代わりに`Effect.matchEffect`を使用しています。`Effect.matchEffect`関数を使用すると、成功と失敗のケースを処理しながら追加の副作用を実行することができます。これにより、メッセージのログやその他の副作用をそれぞれのハンドラ内で行うことができます。

## matchCause / matchCauseEffect

Effectはまた、`Effect.matchCause`および`Effect.matchCauseEffect`関数も提供しています。これらの関数は、失敗した場合に基礎となるファイバーの完全な原因にアクセスするのに役立ちます。これにより、異なる失敗原因を個別に処理し、適切な対応を取ることができます。以下はその例です：

```ts twoslash
import { Effect, Console } from "effect"

declare const exceptionalEffect: Effect.Effect<void, Error>

const program = Effect.matchCauseEffect(exceptionalEffect, {
  onFailure: (cause) => {
    switch (cause._tag) {
      case "Fail":
        return Console.log(`Fail: ${cause.error.message}`)
      case "Die":
        return Console.log(`Die: ${cause.defect}`)
      case "Interrupt":
        return Console.log(`${cause.fiberId} interrupted!`)
    }
    return Console.log("failed due to other causes")
  },
  onSuccess: (value) => Console.log(`succeeded with ${value} value`)
})
```

この例では、`exceptionalEffect`が失敗したり、他の種類の例外に遭遇したりする可能性があります。`matchCauseEffect`関数を使用すると、異なる失敗原因を個別にマッチングして処理することができます。
