---
title: エラー蓄積
excerpt: "`Effect.zip`や`Effect.forEach`などのシーケンシャルコンビネータを探索することで、Effectプログラミングにおけるエラー処理方法を発見しましょう。「フェイルファスト」ポリシーについて学び、`Effect.validate`、`Effect.validateAll`、`Effect.validateFirst`、`Effect.partition`などの関数を使用してエラーを蓄積するための代替アプローチを探りましょう。"
bottomNavigation: pagination
---

`Effect.zip`や`Effect.forEach`などのシーケンシャルコンビネータは、エラー管理において「フェイルファスト」ポリシーを持っています。これは、最初のエラーに遭遇した時点で停止し、直ちに返すことを意味します。

`Effect.zip`オペレータを使用した例を見てみましょう。この例では、`Effect.zip`が最初の失敗に遭遇した時点で失敗することがわかります。その結果、最初のエラーのみが表示されます：

```ts twoslash
import { Effect } from "effect"

const task1 = Effect.succeed(1)
const task2 = Effect.fail("Oh uh!").pipe(Effect.as(2))
const task3 = Effect.succeed(3)
const task4 = Effect.fail("Oh no!").pipe(Effect.as(4))

const program = task1.pipe(
  Effect.zip(task2),
  Effect.zip(task3),
  Effect.zip(task4)
)

Effect.runPromise(program).then(console.log, console.error)
/*
出力:
(FiberFailure) Error: Oh uh!
*/
```

`Effect.forEach`関数も同様に動作します。これは、コレクションと効果的な操作を受け取り、コレクションのすべての要素に対して操作を適用しようとします。しかし、最初のエラーに遭遇した時点で失敗する「フェイルファスト」ポリシーに従います。

```ts twoslash
import { Effect } from "effect"

const program = Effect.forEach([1, 2, 3, 4, 5], (n) => {
  if (n < 4) {
    return Effect.succeed(n)
  } else {
    return Effect.fail(`${n} is not less that 4`)
  }
})

Effect.runPromise(program).then(console.log, console.error)
/*
出力:
(FiberFailure) Error: 4 is not less that 4
*/
```

しかし、フェイルファストではなく、計算中のすべての潜在的なエラーを収集する必要がある状況もあります。そのような場合には、エラーと成功の両方を蓄積するオペレータを使用できます。

## validate

`Effect.validate` 関数は `Effect.zip` に似ていますが、エラーに遭遇しても停止せずに zip 操作を続行します。これにより、エフェクトを結合し、エラーと成功の両方を蓄積します：

```ts twoslash
import { Effect } from "effect"

const task1 = Effect.succeed(1)
const task2 = Effect.fail("Oh uh!").pipe(Effect.as(2))
const task3 = Effect.succeed(3)
const task4 = Effect.fail("Oh no!").pipe(Effect.as(4))

const program = task1.pipe(
  Effect.validate(task2),
  Effect.validate(task3),
  Effect.validate(task4)
)

Effect.runPromise(program).then(console.log, console.error)
/*
出力:
(FiberFailure) Error: Oh uh!
Error: Oh no!
*/
```

`Effect.validate`を使用すると、最初のエラーで停止するのではなく、計算中に遭遇したすべてのエラーを収集できます。これにより、プログラム内のすべての潜在的なエラーと成功の全体像を把握することができます。

## validateAll

`Effect.validateAll`関数は`Effect.forEach`関数に似ています。これは、提供された効果的な操作を使用してコレクションのすべての要素を変換しますが、エラーチャネルにすべてのエラーを収集し、成功チャネルに成功値を収集します。

```ts twoslash
import { Effect } from "effect"

const program = Effect.validateAll([1, 2, 3, 4, 5], (n) => {
  if (n < 4) {
    return Effect.succeed(n)
  } else {
    return Effect.fail(`${n} is not less that 4`)
  }
})

Effect.runPromise(program).then(console.log, console.error)
/*
出力:
(FiberFailure) Error: ["4 is not less that 4","5 is not less that 4"]
*/
```

<Warning>
  この関数は損失があることに注意してください。
  つまり、エラーが発生した場合、すべての成功が失われます。
  成功と失敗の両方を保持する関数が必要な場合は、[partition](#partition)
  関数を参照してください。
</Warning>

## validateFirst

`Effect.validateFirst` 関数は `Effect.validateAll` に似ていますが、最初の成功（またはすべての失敗）を返します。

```ts twoslash
import { Effect } from "effect"

const program = Effect.validateFirst([1, 2, 3, 4, 5], (n) => {
  if (n < 4) {
    return Effect.fail(`${n} is not less that 4`)
  } else {
    return Effect.succeed(n)
  }
})

Effect.runPromise(program).then(console.log, console.error)
// 出力: 4
```

戻り値の型が `validateAll` の場合の `number[]` ではなく、`number` であることに注意してください。

## partition

`Effect.partition` 関数は、イテラブルとそのイテラブルの各値を変換する効果的な関数を受け取ります。次に、成功チャネルに失敗と成功の両方のタプルを作成します。

```ts twoslash
import { Effect } from "effect"

const program = Effect.partition([0, 1, 2, 3, 4], (n) => {
  if (n % 2 === 0) {
    return Effect.succeed(n)
  } else {
    return Effect.fail(`${n} is not even`)
  }
})

Effect.runPromise(program).then(console.log, console.error)
// 出力: [ [ '1 is not even', '3 is not even' ], [ 0, 2, 4 ] ]
```

このオペレーターは例外のないエフェクトであることに注意してください。つまり、エラーチャネルの型は `never` です。したがって、失敗ケースに遭遇しても、全体のエフェクトは失敗しません。
