---
title: Streamにおけるエラーハンドリング
navTitle: エラーハンドリング
excerpt: `orElse`のような関数を使用してシームレスにリカバリーし、`catchAll`で高度なエラーハンドリングを行い、一時的な失敗を処理するために`retry`を使用して、ストリーム内のエラーを効果的に処理します。エラーを洗練し、さまざまなオペレーターでタイムアウトを設定し、欠陥から優雅に回復する方法を学び、アプリケーションの堅牢なストリーム処理を確保します。
bottomNavigation: pagination
---

## 障害からの回復

エラーが発生する可能性のあるストリームを扱う際には、これらのエラーを優雅に処理する方法を知ることが重要です。`Stream.orElse`関数は、失敗から回復し、エラーが発生した場合に代替ストリームに切り替えるための強力なツールです。

ここに実用的な例があります：

```ts twoslash
import { Stream, Effect } from "effect"

const s1 = Stream.make(1, 2, 3).pipe(
  Stream.concat(Stream.fail("Oh! Error!")),
  Stream.concat(Stream.make(4, 5))
)

const s2 = Stream.make("a", "b", "c")

const stream = Stream.orElse(s1, () => s2)

Effect.runPromise(Stream.runCollect(stream)).then(console.log)
/*
出力:
{
  _id: "Chunk",
  values: [ 1, 2, 3, "a", "b", "c" ]
}
*/
```

この例では、`s1`がエラーに遭遇しますが、ストリームを終了する代わりに、`Stream.orElse`を使用して優雅に`s2`に切り替えます。これにより、1つのストリームが失敗してもデータの処理を続行することができます。

また、成功か失敗かに基づいて2つのストリームの要素を区別するために[Either](../../../other/data-types/either)データ型を使用する`Stream.orElseEither`というバリアントもあります：

```ts twoslash
import { Stream, Effect } from "effect"

const s1 = Stream.make(1, 2, 3).pipe(
  Stream.concat(Stream.fail("Oh! Error!")),
  Stream.concat(Stream.make(4, 5))
)

const s2 = Stream.make("a", "b", "c")

const stream = Stream.orElseEither(s1, () => s2)

Effect.runPromise(Stream.runCollect(stream)).then(console.log)
/*
出力:
{
  _id: "Chunk",
  values: [
    {
      _id: "Either",
      _tag: "Left",
      left: 1
    }, {
      _id: "Either",
      _tag: "Left",
      left: 2
    }, {
      _id: "Either",
      _tag: "Left",
      left: 3
    }, {
      _id: "Either",
      _tag: "Right",
      right: "a"
    }, {
      _id: "Either",
      _tag: "Right",
      right: "b"
    }, {
      _id: "Either",
      _tag: "Right",
      right: "c"
    }
  ]
}
*/
```

`Stream.catchAll`関数は、`Stream.orElse`と比較して高度なエラーハンドリング機能を提供します。`Stream.catchAll`を使用すると、遭遇した失敗のタイプと値の両方に基づいて判断を下すことができます。

```ts twoslash
import { Stream, Effect } from "effect"

const s1 = Stream.make(1, 2, 3).pipe(
  Stream.concat(Stream.fail("Uh Oh!" as const)),
  Stream.concat(Stream.make(4, 5)),
  Stream.concat(Stream.fail("Ouch" as const))
)

const s2 = Stream.make("a", "b", "c")

const s3 = Stream.make(true, false, false)

const stream = Stream.catchAll(
  s1,
  (error): Stream.Stream<string | boolean> => {
    switch (error) {
      case "Uh Oh!":
        return s2
      case "Ouch":
        return s3
    }
  }
)

Effect.runPromise(Stream.runCollect(stream)).then(console.log)
/*
出力:
{
  _id: "Chunk",
  values: [ 1, 2, 3, "a", "b", "c" ]
}
*/
```

この例では、`s1`というストリームがあり、2種類の異なるエラーに遭遇する可能性があります。`Stream.orElse`で行うような単純な代替ストリームへの切り替えの代わりに、`Stream.catchAll`を使用して各エラータイプの処理方法を正確に決定します。このレベルのエラー回復制御により、特定のエラー条件に基づいて異なるストリームやアクションを選択することができます。

## Defectsからの回復

ストリームを扱う際には、ストリーム処理中に発生する可能性のあるDefectsを含むさまざまな失敗シナリオに備えることが重要です。これに対処するために、`Stream.catchAllCause`関数は堅牢なソリューションを提供します。これにより、発生する可能性のあるあらゆる種類の失敗を優雅に処理し、回復することができます。

以下はその使用例を示しています：

```ts twoslash
import { Stream, Effect } from "effect"

const s1 = Stream.make(1, 2, 3).pipe(
  Stream.concat(Stream.dieMessage("Boom!")),
  Stream.concat(Stream.make(4, 5))
)

const s2 = Stream.make("a", "b", "c")

const stream = Stream.catchAllCause(s1, () => s2)

Effect.runPromise(Stream.runCollect(stream)).then(console.log)
/*
出力:
{
  _id: "Chunk",
  values: [ 1, 2, 3, "a", "b", "c" ]
}
*/
```

この例では、`s1`が欠陥に遭遇する可能性がありますが、アプリケーションをクラッシュさせる代わりに、`Stream.catchAllCause`を使用して代替ストリームの`s2`に優雅に切り替えます。これにより、予期しない問題が発生してもアプリケーションが堅牢であり続け、データの処理を継続することができます。

## 一部のエラーからの回復

ストリーム処理では、特定の種類の失敗から回復する必要がある状況があるかもしれません。`Stream.catchSome`および`Stream.catchSomeCause`関数が役立ち、エラーを選択的に処理および軽減することができます。

特定のエラーから回復したい場合は、`Stream.catchSome`を使用できます：

```ts twoslash
import { Stream, Effect, Option } from "effect"

const s1 = Stream.make(1, 2, 3).pipe(
  Stream.concat(Stream.fail("Oh! Error!")),
  Stream.concat(Stream.make(4, 5))
)

const s2 = Stream.make("a", "b", "c")

const stream = Stream.catchSome(s1, (error) => {
  if (error === "Oh! Error!") {
    return Option.some(s2)
  }
  return Option.none()
})

Effect.runPromise(Stream.runCollect(stream)).then(console.log)
/*
出力:
{
  _id: "Chunk",
  values: [ 1, 2, 3, "a", "b", "c" ]
}
*/
```

特定の原因から回復するためには、`Stream.catchSomeCause`関数を使用できます：

```ts twoslash
import { Stream, Effect, Option, Cause } from "effect"

const s1 = Stream.make(1, 2, 3).pipe(
  Stream.concat(Stream.dieMessage("Oh! Error!")),
  Stream.concat(Stream.make(4, 5))
)

const s2 = Stream.make("a", "b", "c")

const stream = Stream.catchSomeCause(s1, (cause) => {
  if (Cause.isDie(cause)) {
    return Option.some(s2)
  }
  return Option.none()
})

Effect.runPromise(Stream.runCollect(stream)).then(console.log)
/*
出力:
{
  _id: "Chunk",
  values: [ 1, 2, 3, "a", "b", "c" ]
}
*/
```

## Effectへのリカバリー

ストリーム処理において、エラーを優雅に処理し、必要に応じてクリーンアップタスクを実行することが重要です。`Stream.onError`関数を使用すると、それが可能になります。ストリームがエラーに遭遇した場合、クリーンアップタスクを指定して実行することができます。

```ts twoslash
import { Stream, Console, Effect } from "effect"

const stream = Stream.make(1, 2, 3).pipe(
  Stream.concat(Stream.dieMessage("Oh! Boom!")),
  Stream.concat(Stream.make(4, 5)),
  Stream.onError(() =>
    Console.log(
      "Stream application closed! We are doing some cleanup jobs."
    ).pipe(Effect.orDie)
  )
)

Effect.runPromise(Stream.runCollect(stream)).then(console.log)
/*
出力:
Stream application closed! We are doing some cleanup jobs.
error: RuntimeException: Oh! Boom!
*/
```

## 失敗したストリームのリトライ

時々、ストリームは一時的または回復可能な失敗に遭遇することがあります。そのような場合、`Stream.retry`オペレーターが役立ちます。これにより、リトライスケジュールを指定することができ、そのスケジュールに従ってストリームがリトライされます。

以下はその動作を示す例です：

```ts twoslash
// @types: node
import { Stream, Effect, Schedule } from "effect"
import * as NodeReadLine from "node:readline"

const stream = Stream.make(1, 2, 3).pipe(
  Stream.concat(
    Stream.fromEffect(
      Effect.gen(function* () {
        const s = yield* readLine("Enter a number: ")
        const n = parseInt(s)
        if (Number.isNaN(n)) {
          return yield* Effect.fail("NaN")
        }
        return n
      })
    ).pipe(Stream.retry(Schedule.exponential("1 second")))
  )
)

Effect.runPromise(Stream.runCollect(stream)).then(console.log)
/*
出力:
Enter a number: a
Enter a number: b
Enter a number: c
Enter a number: 4
{
  _id: "Chunk",
  values: [ 1, 2, 3, 4 ]
}
*/

const readLine = (message: string): Effect.Effect<string> =>
  Effect.promise(
    () =>
      new Promise((resolve) => {
        const rl = NodeReadLine.createInterface({
          input: process.stdin,
          出力: process.stdout
        })
        rl.question(message, (answer) => {
          rl.close()
          resolve(answer)
        })
      })
  )
```

この例では、ストリームがユーザーに数値を入力するように求めますが、無効な値（例："a"、"b"、"c"）が入力されると、"NaN"で失敗します。しかし、`Stream.retry`を指数バックオフスケジュールで使用するため、遅延時間が増加するごとに再試行します。これにより、一時的なエラーを処理し、最終的に有効な入力を収集することができます。

## エラーの精査

ストリームを扱う際に、特定のエラーを選択的に保持し、残りのエラーでストリームを終了させたい場合があります。これを実現するには、`Stream.refineOrDie`関数を使用できます。

以下はその動作を示す例です。

```ts twoslash
import { Stream, Option } from "effect"

const stream = Stream.fail(new Error())

const res = Stream.refineOrDie(stream, (error) => {
  if (error instanceof SyntaxError) {
    return Option.some(error)
  }
  return Option.none()
})
```

この例では、`stream`は最初に一般的な`Error`で失敗します。しかし、`Stream.refineOrDie`を使用して、`SyntaxError`タイプのエラーのみをフィルタリングして保持します。他のエラーは終了されますが、`SyntaxError`は`refinedStream`に保持されます。

## タイムアウト

ストリームを扱う際に、特定の期間内に値を生成しない場合にストリームを終了させるなど、タイムアウトを処理したいシナリオがあります。このセクションでは、さまざまなオペレーターを使用してタイムアウトを管理する方法を探ります。

### timeout

`Stream.timeout`オペレーターを使用すると、ストリームにタイムアウトを設定できます。ストリームが指定された期間内に値を生成しない場合、終了します。

```ts twoslash
import { Stream, Effect } from "effect"

const stream = Stream.fromEffect(Effect.never).pipe(
  Stream.timeout("2 seconds")
)

Effect.runPromise(Stream.runCollect(stream)).then(console.log)
/*
{
  _id: "Chunk",
  values: []
}
*/
```

### timeoutFail

`Stream.timeoutFail`オペレーターは、タイムアウトとカスタムエラーメッセージを組み合わせます。ストリームがタイムアウトすると、指定されたエラーメッセージで失敗します。

```ts twoslash
import { Stream, Effect } from "effect"

const stream = Stream.fromEffect(Effect.never).pipe(
  Stream.timeoutFail(() => "timeout", "2 seconds")
)

Effect.runPromiseExit(Stream.runCollect(stream)).then(console.log)
/*
出力:
{
  _id: 'Exit',
  _tag: 'Failure',
  cause: { _id: 'Cause', _tag: 'Fail', failure: 'timeout' }
}
*/
```

### timeoutFailCause

`Stream.timeoutFail`と同様に、`Stream.timeoutFailCause`はタイムアウトとカスタム失敗原因を組み合わせます。ストリームがタイムアウトすると、指定された原因で失敗します。

```ts twoslash
import { Stream, Effect, Cause } from "effect"

const stream = Stream.fromEffect(Effect.never).pipe(
  Stream.timeoutFailCause(() => Cause.die("timeout"), "2 seconds")
)

Effect.runPromiseExit(Stream.runCollect(stream)).then(console.log)
/*
出力:
{
  _id: 'Exit',
  _tag: 'Failure',
  cause: { _id: 'Cause', _tag: 'Die', defect: 'timeout' }
}
*/
```

### timeoutTo

`Stream.timeoutTo`オペレーターは、最初のストリームが指定された期間内に値を生成しない場合に、別のストリームに切り替えることができます。

```ts twoslash
import { Stream, Effect } from "effect"

const stream = Stream.fromEffect(Effect.never).pipe(
  Stream.timeoutTo("2 seconds", Stream.make(1, 2, 3))
)

Effect.runPromise(Stream.runCollect(stream)).then(console.log)
/*
{
  _id: "Chunk",
  values: [ 1, 2, 3 ]
}
*/
```
